File: lab4/Specimen_RawData_1.csv
Time,Extension,Load
(s),(mm),(N)
"0.00000","0.00000","-0.53872"
"0.20000","0.00000","-0.04951"
"0.40000","0.00021","-0.05157"
"0.60000","0.00048","1.28427"
"0.80000","0.00064","2.69330"
"1.00000","0.00086","4.15947"
"1.20000","0.00102","5.97136"
"1.40000","0.00118","7.73227"
"1.60000","0.00134","9.58572"
"1.80000","0.00150","11.05370"
"2.00000","0.00171","12.72084"
"2.20000","0.00187","14.20387"
"2.40000","0.00204","16.00433"
"2.60000","0.00220","17.27960"
"2.80000","0.00236","18.63333"
"3.00000","0.00252","20.06060"
"3.20000","0.00273","21.16048"
"3.40000","0.00289","22.45700"
"3.60000","0.00305","23.81643"
"3.80000","0.00321","25.08350"
"4.00000","0.00343","26.26028"
"4.20000","0.00359","28.00241"
"4.40000","0.00375","29.04811"
"4.60000","0.00391","30.51958"
"4.80000","0.00407","31.13799"
"5.00000","0.00423","32.41362"
"5.20000","0.00439","33.45663"
"5.40000","0.00455","34.62509"
"5.60000","0.00471","35.72498"
"5.80000","0.00487","36.73937"
"6.00000","0.00504","37.54799"
"6.20000","0.00520","38.80529"
"6.40000","0.00536","39.76044"
"6.60000","0.00552","41.23104"
"6.80000","0.00568","41.96927"
"7.00000","0.00584","43.23697"
"7.20000","0.00600","44.25051"
"7.40000","0.00616","45.12373"
"7.60000","0.00637","46.02855"
"7.80000","0.00654","47.31627"
"8.00000","0.00670","48.23674"
"8.20000","0.00691","49.57970"
"8.40000","0.00707","50.64613"
"8.60000","0.00723","51.54868"
"8.80000","0.00745","52.69029"
"9.00000","0.00761","53.48384"
"9.20000","0.00777","54.50529"
"9.40000","0.00793","55.33751"
"9.60000","0.00809","56.50091"
"9.80000","0.00825","57.39642"
"10.00000","0.00841","58.31704"
"10.20000","0.00857","59.04487"
"10.40000","0.00879","60.13023"
"10.60000","0.00895","60.86057"
"10.80000","0.00911","61.99218"
"11.00000","0.00927","62.65660"
"11.20000","0.00943","63.55977"
"11.40000","0.00959","64.34741"
"11.60000","0.00975","65.12404"
"11.80000","0.00991","66.07967"
"12.00000","0.01007","66.80543"
"12.20000","0.01023","67.78153"
"12.40000","0.01034","68.36233"
"12.60000","0.01050","69.27322"
"12.80000","0.01066","70.01801"
"13.00000","0.01082","70.77538"
"13.20000","0.01104","71.73031"
"13.40000","0.01120","72.59602"
"13.60000","0.01136","73.28632"
"13.80000","0.01152","74.06898"
"14.00000","0.01168","74.85722"
"14.20000","0.01184","75.95649"
"14.40000","0.01205","76.52599"
"14.60000","0.01221","77.26581"
"14.80000","0.01237","78.22703"
"15.00000","0.01254","78.99326"
"15.20000","0.01270","79.76294"
"15.40000","0.01291","80.72311"
"15.60000","0.01307","81.29028"
"15.80000","0.01323","81.92270"
"16.00000","0.01339","82.84560"
"16.20000","0.01361","83.35079"
"16.40000","0.01377","84.11858"
"16.60000","0.01393","85.03901"
"16.80000","0.01409","85.62540"
"17.00000","0.01425","86.36587"
"17.20000","0.01441","86.80785"
"17.40000","0.01457","87.42467"
"17.60000","0.01473","88.14649"
"17.80000","0.01489","88.56412"
"18.00000","0.01505","89.03088"
"18.20000","0.01516","89.82050"
"18.40000","0.01532","90.42825"
"18.60000","0.01554","91.36540"
"18.80000","0.01570","91.84497"
"19.00000","0.01586","92.35457"
"19.20000","0.01602","93.10260"
"19.40000","0.01618","93.84290"
"19.60000","0.01634","94.57050"
"19.80000","0.01650","95.07028"
"20.00000","0.01671","95.67583"
"20.20000","0.01687","96.44279"
"20.40000","0.01704","97.19420"
"20.60000","0.01725","98.11436"
"20.80000","0.01741","98.66084"
"21.00000","0.01757","99.18724"
"21.20000","0.01773","99.84415"
"21.40000","0.01795","100.42352"
"21.60000","0.01811","101.20666"
"21.80000","0.01827","101.59550"
"22.00000","0.01843","102.26157"
"22.20000","0.01859","103.12429"
"22.40000","0.01875","103.74664"
"22.60000","0.01891","104.36437"
"22.80000","0.01907","105.02783"
"23.00000","0.01929","105.66856"
"23.20000","0.01945","106.47236"
"23.40000","0.01961","106.89224"
"23.60000","0.01977","107.56478"
"23.80000","0.01993","108.40379"
"24.00000","0.02009","109.22845"
"24.20000","0.02025","109.75762"
"24.40000","0.02041","110.22987"
"24.60000","0.02052","110.82047"
"24.80000","0.02068","111.24395"
"25.00000","0.02084","112.00184"
"25.20000","0.02100","112.88937"
"25.40000","0.02116","113.59438"
"25.60000","0.02132","114.27004"
"25.80000","0.02154","115.07599"
"26.00000","0.02170","115.86640"
"26.20000","0.02186","116.38451"
"26.40000","0.02202","117.15542"
"26.60000","0.02218","117.95950"
"26.80000","0.02239","118.84607"
"27.00000","0.02255","119.44223"
"27.20000","0.02271","120.09006"
"27.40000","0.02287","120.80386"
"27.60000","0.02309","121.55841"
"27.80000","0.02325","122.36558"
"28.00000","0.02341","123.14796"
"28.20000","0.02357","123.72746"
"28.40000","0.02379","124.32185"
"28.60000","0.02395","125.14178"
"28.80000","0.02411","125.92394"
"29.00000","0.02427","126.42054"
"29.20000","0.02443","127.29743"
"29.40000","0.02459","128.07291"
"29.60000","0.02475","128.52875"
"29.80000","0.02491","129.44533"
"30.00000","0.02507","130.07901"
"30.20000","0.02523","130.31766"
"30.40000","0.02539","130.83975"
"30.60000","0.02550","131.59438"
"30.80000","0.02566","132.04958"
"31.00000","0.02582","132.73537"
"31.20000","0.02604","133.63699"
"31.40000","0.02620","133.78659"
"31.60000","0.02636","134.62796"
"31.80000","0.02652","135.12842"
"32.00000","0.02668","135.53104"
"32.20000","0.02684","136.08015"
"32.40000","0.02705","136.62077"
"32.60000","0.02721","137.19392"
"32.80000","0.02743","137.90964"
"33.00000","0.02759","138.60771"
"33.20000","0.02775","138.93283"
"33.40000","0.02791","140.00769"
"33.60000","0.02807","140.30974"
"33.80000","0.02823","141.08731"
"34.00000","0.02845","141.78571"
"34.20000","0.02861","142.77673"
"34.40000","0.02877","143.52396"
"34.60000","0.02893","144.36359"
"34.80000","0.02909","145.33916"
"35.00000","0.02925","146.07344"
"35.20000","0.02941","146.92441"
"35.40000","0.02957","147.70758"
"35.60000","0.02979","148.55634"
"35.80000","0.02995","149.19972"
"36.00000","0.03011","149.97797"
"36.20000","0.03027","150.85536"
"36.40000","0.03043","151.52132"
"36.60000","0.03059","151.73875"
"36.80000","0.03070","152.69122"
"37.00000","0.03086","152.94595"
"37.20000","0.03102","153.86243"
"37.40000","0.03118","154.39085"
"37.60000","0.03134","155.12517"
"37.80000","0.03150","155.98816"
"38.00000","0.03166","156.33064"
"38.20000","0.03187","157.06490"
"38.40000","0.03204","157.53888"
"38.60000","0.03220","158.28360"
"38.80000","0.03236","158.84694"
"39.00000","0.03257","159.22580"
"39.20000","0.03273","159.63095"
"39.40000","0.03289","160.24091"
"39.60000","0.03311","161.04877"
"39.80000","0.03327","161.09145"
"40.00000","0.03343","161.33824"
"40.20000","0.03359","161.91269"
"40.40000","0.03375","162.02290"
"40.60000","0.03391","162.49750"
"40.80000","0.03407","162.91751"
"41.00000","0.03423","162.99481"
"41.20000","0.03445","163.29407"
"41.40000","0.03461","163.52084"
"41.60000","0.03477","164.06288"
"41.80000","0.03493","163.83365"
"42.00000","0.03509","164.27904"
"42.20000","0.03525","164.67815"
"42.40000","0.03541","164.94537"
"42.60000","0.03552","165.04573"
"42.80000","0.03568","165.38161"
"43.00000","0.03584","165.86980"
"43.20000","0.03600","166.06270"
"43.40000","0.03616","166.45609"
"43.60000","0.03638","167.01305"
"43.80000","0.03654","167.10512"
"44.00000","0.03670","167.41342"
"44.20000","0.03686","167.86929"
"44.40000","0.03702","168.37404"
"44.60000","0.03718","168.62157"
"44.80000","0.03739","169.24590"
"45.00000","0.03755","169.23257"
"45.20000","0.03777","169.62335"
"45.40000","0.03793","169.87628"
"45.60000","0.03809","170.29697"
"45.80000","0.03825","170.64224"
"46.00000","0.03841","170.99582"
"46.20000","0.03857","171.19858"
"46.40000","0.03873","171.52417"
"46.60000","0.03895","171.63885"
"46.80000","0.03911","172.06551"
"47.00000","0.03927","172.33086"
"47.20000","0.03943","172.57430"
"47.40000","0.03959","173.13029"
"47.60000","0.03975","173.20444"
"47.80000","0.03991","173.70006"
"48.00000","0.04007","173.72911"
"48.20000","0.04023","174.11404"
"48.40000","0.04045","173.85701"
"48.60000","0.04061","174.30194"
"48.80000","0.04071","174.50987"
"49.00000","0.04087","174.74074"
"49.20000","0.04104","174.93268"
"49.40000","0.04120","175.28070"
"49.60000","0.04136","175.33122"
"49.80000","0.04152","175.63187"
"50.00000","0.04168","175.87073"
"50.20000","0.04184","176.48633"
"50.40000","0.04200","176.83044"
"50.60000","0.04221","177.05513"
"50.80000","0.04237","177.38487"
"51.00000","0.04254","177.69116"
"51.20000","0.04270","177.99710"
"51.40000","0.04291","178.57080"
"51.60000","0.04307","178.70378"
"51.80000","0.04323","178.87784"
"52.00000","0.04339","179.18454"
"52.20000","0.04361","179.83685"
"52.40000","0.04377","180.28134"
"52.60000","0.04393","180.92772"
"52.80000","0.04409","181.58690"
"53.00000","0.04425","182.95940"
"53.20000","0.04441","183.86833"
"53.40000","0.04457","184.82417"
"53.60000","0.04473","185.97923"
"53.80000","0.04495","187.13681"
"54.00000","0.04511","187.93318"
"54.20000","0.04527","188.39687"
"54.40000","0.04543","189.47745"
"54.60000","0.04554","190.63718"
"54.80000","0.04570","191.60860"
"55.00000","0.04586","192.51115"
"55.20000","0.04602","193.70724"
"55.40000","0.04618","194.70268"
"55.60000","0.04634","196.17221"
"55.80000","0.04650","197.22804"
"56.00000","0.04666","198.81897"
"56.20000","0.04687","199.92641"
"56.40000","0.04704","201.17305"
"56.60000","0.04720","202.47139"
"56.80000","0.04736","204.06993"
"57.00000","0.04752","205.07069"
"57.20000","0.04773","206.30733"
"57.40000","0.04789","207.95097"
"57.60000","0.04811","209.31943"
"57.80000","0.04827","210.46581"
"58.00000","0.04843","211.87477"
"58.20000","0.04859","213.07675"
"58.40000","0.04875","214.32581"
"58.60000","0.04891","215.70993"
"58.80000","0.04907","216.94292"
"59.00000","0.04929","218.30423"
"59.20000","0.04945","219.44676"
"59.40000","0.04961","220.82254"
"59.60000","0.04977","221.82933"
"59.80000","0.04993","223.26202"
"60.00000","0.05009","224.46123"
"60.20000","0.05025","225.75728"
"60.40000","0.05041","227.00394"
"60.60000","0.05057","228.29720"
"60.80000","0.05073","229.48370"
"61.00000","0.05089","230.76593"
"61.20000","0.05105","231.83974"
"61.40000","0.05121","232.97209"
"61.60000","0.05132","234.08286"
"61.80000","0.05154","235.41808"
"62.00000","0.05170","236.84970"
"62.20000","0.05186","238.40898"
"62.40000","0.05202","239.25410"
"62.60000","0.05218","241.14154"
"62.80000","0.05234","242.52003"
"63.00000","0.05255","243.86177"
"63.20000","0.05271","245.48236"
"63.40000","0.05287","246.98001"
"63.60000","0.05309","248.51578"
"63.80000","0.05325","250.12602"
"64.00000","0.05341","251.51401"
"64.20000","0.05357","253.21919"
"64.40000","0.05373","254.64021"
"64.60000","0.05395","256.19473"
"64.80000","0.05411","257.94061"
"65.00000","0.05427","259.23108"
"65.20000","0.05443","260.83887"
"65.40000","0.05459","262.59985"
"65.60000","0.05475","264.11755"
"65.80000","0.05491","265.84714"
"66.00000","0.05507","267.52591"
"66.20000","0.05523","268.86859"
"66.40000","0.05539","270.56958"
"66.60000","0.05555","272.05585"
"66.80000","0.05571","273.72760"
"67.00000","0.05587","275.21594"
"67.20000","0.05604","276.40067"
"67.40000","0.05620","277.83658"
"67.60000","0.05636","279.68634"
"67.80000","0.05652","281.13022"
"68.00000","0.05668","282.83633"
"68.20000","0.05684","284.47925"
"68.40000","0.05700","286.18027"
"68.60000","0.05716","287.80035"
"68.80000","0.05737","289.46356"
"69.00000","0.05754","291.12683"
"69.20000","0.05770","292.63184"
"69.40000","0.05786","294.47870"
"69.60000","0.05807","296.02911"
"69.80000","0.05823","297.91269"
"70.00000","0.05845","299.72708"
"70.20000","0.05861","301.05301"
"70.40000","0.05877","302.59320"
"70.60000","0.05893","304.27209"
"70.80000","0.05909","305.46109"
"71.00000","0.05925","307.28052"
"71.20000","0.05941","308.49286"
"71.40000","0.05962","310.29990"
"71.60000","0.05979","311.96356"
"71.80000","0.05995","313.50586"
"72.00000","0.06011","315.11072"
"72.20000","0.06027","316.30688"
"72.40000","0.06043","318.08865"
"72.60000","0.06059","319.67529"
"72.80000","0.06075","321.01129"
"73.00000","0.06091","322.58163"
"73.20000","0.06107","324.48798"
"73.40000","0.06123","325.72891"
"73.60000","0.06139","327.19727"
"73.80000","0.06150","328.46100"
"74.00000","0.06166","329.85028"
"74.20000","0.06182","331.20764"
"74.40000","0.06198","333.15259"
"74.60000","0.06220","334.73126"
"74.80000","0.06236","336.43961"
"75.00000","0.06252","338.39996"
"75.20000","0.06268","339.79453"
"75.40000","0.06284","341.58786"
"75.60000","0.06305","343.74326"
"75.80000","0.06321","344.95544"
"76.00000","0.06338","346.85010"
"76.20000","0.06359","348.31616"
"76.40000","0.06375","350.35800"
"76.60000","0.06391","352.14929"
"76.80000","0.06407","353.48679"
"77.00000","0.06423","355.46613"
"77.20000","0.06445","356.81879"
"77.40000","0.06461","358.43442"
"77.60000","0.06477","360.03268"
"77.80000","0.06493","361.85297"
"78.00000","0.06509","363.23898"
"78.20000","0.06525","364.81677"
"78.40000","0.06541","366.47858"
"78.60000","0.06557","368.11655"
"78.80000","0.06573","369.64252"
"79.00000","0.06589","371.05371"
"79.20000","0.06605","372.60721"
"79.40000","0.06621","374.09528"
"79.60000","0.06632","375.37234"
"79.80000","0.06654","377.06900"
"80.00000","0.06670","378.40546"
"80.20000","0.06686","380.12888"
"80.40000","0.06702","381.91513"
"80.60000","0.06718","383.52808"
"80.80000","0.06734","385.10718"
"81.00000","0.06750","386.43024"
"81.20000","0.06771","388.56534"
"81.40000","0.06787","390.17850"
"81.60000","0.06804","392.04764"
"81.80000","0.06825","393.57150"
"82.00000","0.06841","395.25494"
"82.20000","0.06857","397.19598"
"82.40000","0.06873","398.65964"
"82.60000","0.06895","400.26892"
"82.80000","0.06911","401.92502"
"83.00000","0.06927","403.71652"
"83.20000","0.06943","405.19183"
"83.40000","0.06959","406.81314"
"83.60000","0.06975","408.59988"
"83.80000","0.06991","410.32275"
"84.00000","0.07007","411.87137"
"84.20000","0.07029","413.54614"
"84.40000","0.07045","415.13483"
"84.60000","0.07061","416.44443"
"84.80000","0.07077","418.31943"
"85.00000","0.07093","420.04153"
"85.20000","0.07109","421.41397"
"85.40000","0.07125","423.08945"
"85.60000","0.07141","424.56577"
"85.80000","0.07152","426.35373"
"86.00000","0.07168","427.57205"
"86.20000","0.07184","428.81299"
"86.40000","0.07200","430.77493"
"86.60000","0.07216","432.27191"
"86.80000","0.07232","434.00653"
"87.00000","0.07254","435.74164"
"87.20000","0.07270","437.28784"
"87.40000","0.07286","439.07358"
"87.60000","0.07302","440.88037"
"87.80000","0.07318","442.48462"
"88.00000","0.07339","444.26114"
"88.20000","0.07355","445.91058"
"88.40000","0.07371","447.49234"
"88.60000","0.07387","449.44174"
"88.80000","0.07409","451.04303"
"89.00000","0.07425","452.75269"
"89.20000","0.07441","454.45166"
"89.40000","0.07457","455.97647"
"89.60000","0.07473","457.76987"
"89.80000","0.07495","459.46332"
"90.00000","0.07511","460.88525"
"90.20000","0.07527","462.60541"
"90.40000","0.07543","464.37262"
"90.60000","0.07559","465.73663"
"90.80000","0.07575","467.34674"
"91.00000","0.07591","469.19412"
"91.20000","0.07607","470.80435"
"91.40000","0.07623","471.98083"
"91.60000","0.07639","473.47403"
"91.80000","0.07650","474.87012"
"92.00000","0.07666","476.52512"
"92.20000","0.07682","477.96008"
"92.40000","0.07704","479.84229"
"92.60000","0.07720","481.40082"
"92.80000","0.07736","483.03311"
"93.00000","0.07752","484.61218"
"93.20000","0.07768","486.46536"
"93.40000","0.07784","488.12878"
"93.60000","0.07805","489.66470"
"93.80000","0.07821","491.61023"
"94.00000","0.07843","493.11618"
"94.20000","0.07859","495.05286"
"94.40000","0.07875","496.78494"
"94.60000","0.07891","498.59628"
"94.80000","0.07907","499.94821"
"95.00000","0.07923","501.79962"
"95.20000","0.07945","503.45355"
"95.40000","0.07961","504.81894"
"95.60000","0.07977","506.48712"
"95.80000","0.07993","508.45663"
"96.00000","0.08009","510.01093"
"96.20000","0.08025","511.55164"
"96.40000","0.08041","513.39392"
"96.60000","0.08057","515.15479"
"96.80000","0.08079","516.82166"
"97.00000","0.08095","518.25903"
"97.20000","0.08111","520.26550"
"97.40000","0.08127","521.68921"
"97.60000","0.08143","523.21753"
"97.80000","0.08159","524.93463"
"98.00000","0.08175","526.46082"
"98.20000","0.08186","527.85852"
"98.40000","0.08202","529.17352"
"98.60000","0.08218","530.92877"
"98.80000","0.08234","532.56775"
"99.00000","0.08250","534.45813"
"99.20000","0.08266","535.95770"
"99.40000","0.08287","537.62872"
"99.60000","0.08304","539.56635"
"99.80000","0.08320","541.26141"
"100.00000","0.08336","542.74994"
"100.20000","0.08357","544.57574"
"100.40000","0.08373","546.27112"
"100.60000","0.08389","548.14325"
"100.80000","0.08405","549.81561"
"101.00000","0.08427","551.49506"
"101.20000","0.08443","553.20349"
"101.40000","0.08459","554.68201"
"101.60000","0.08475","556.43982"
"101.80000","0.08491","557.83893"
"102.00000","0.08507","559.60565"
"102.20000","0.08529","561.33820"
"102.40000","0.08545","563.01355"
"102.60000","0.08561","564.45953"
"102.80000","0.08577","566.04150"
"103.00000","0.08593","567.52490"
"103.20000","0.08609","569.30444"
"103.40000","0.08625","570.83685"
"103.60000","0.08641","572.43073"
"103.80000","0.08652","573.96625"
"104.00000","0.08668","575.20575"
"104.20000","0.08684","576.81201"
"104.40000","0.08700","578.43341"
"104.60000","0.08716","580.35046"
"104.80000","0.08732","581.93115"
"105.00000","0.08754","583.51654"
"105.20000","0.08770","585.01080"
"105.40000","0.08786","586.72925"
"105.60000","0.08802","588.68420"
"105.80000","0.08818","590.44647"
"106.00000","0.08839","591.93420"
"106.20000","0.08855","593.97748"
"106.40000","0.08871","595.76343"
"106.60000","0.08893","597.62500"
"106.80000","0.08909","599.18182"
"107.00000","0.08925","600.77118"
"107.20000","0.08941","602.57684"
"107.40000","0.08957","604.17218"
"107.60000","0.08973","605.98901"
"107.80000","0.08995","607.64062"
"108.00000","0.09011","609.48016"
"108.20000","0.09027","610.77655"
"108.40000","0.09043","612.68195"
"108.60000","0.09059","614.37842"
"108.80000","0.09075","615.97314"
"109.00000","0.09091","617.51636"
"109.20000","0.09107","618.98914"
"109.40000","0.09129","620.80029"
"109.60000","0.09145","622.55408"
"109.80000","0.09161","623.65955"
"110.00000","0.09171","625.62158"
"110.20000","0.09188","626.78156"
"110.40000","0.09204","628.26434"
"110.60000","0.09220","629.45245"
"110.80000","0.09236","631.17322"
"111.00000","0.09252","632.77271"
"111.20000","0.09268","634.44873"
"111.40000","0.09284","636.08112"
"111.60000","0.09300","638.02435"
"111.80000","0.09316","639.71582"
"112.00000","0.09337","641.23224"
"112.20000","0.09354","642.91882"
"112.40000","0.09370","644.76385"
"112.60000","0.09386","646.33173"
"112.80000","0.09407","648.35028"
"113.00000","0.09423","650.03809"
"113.20000","0.09439","651.44958"
"113.40000","0.09455","653.52460"
"113.60000","0.09477","655.03760"
"113.80000","0.09493","657.20276"
"114.00000","0.09509","658.54596"
"114.20000","0.09525","660.13605"
"114.40000","0.09541","661.99652"
"114.60000","0.09557","663.61176"
"114.80000","0.09573","665.22424"
"115.00000","0.09595","666.85815"
"115.20000","0.09611","668.52490"
"115.40000","0.09627","670.17950"
"115.60000","0.09643","671.74725"
"115.80000","0.09659","673.36743"
"116.00000","0.09670","674.67273"
"116.20000","0.09686","675.90631"
"116.40000","0.09702","677.61395"
"116.60000","0.09718","679.12805"
"116.80000","0.09734","680.90894"
"117.00000","0.09750","682.69806"
"117.20000","0.09766","684.20538"
"117.40000","0.09782","685.81024"
"117.60000","0.09804","687.74310"
"117.80000","0.09820","689.26361"
"118.00000","0.09836","691.08337"
"118.20000","0.09852","692.73126"
"118.40000","0.09873","694.71387"
"118.60000","0.09889","696.21289"
"118.80000","0.09911","698.15887"
"119.00000","0.09927","699.84454"
"119.20000","0.09943","701.73840"
"119.40000","0.09959","703.30792"
"119.60000","0.09975","704.95599"
"119.80000","0.09991","706.46191"
"120.00000","0.10007","708.47229"
"120.20000","0.10029","709.82910"
"120.40000","0.10045","711.67853"
"120.60000","0.10061","713.49652"
"120.80000","0.10077","715.00024"
"121.00000","0.10093","716.92480"
"121.20000","0.10109","718.40662"
"121.40000","0.10125","720.03229"
"121.60000","0.10141","721.72009"
"121.80000","0.10157","723.37085"
"122.00000","0.10173","725.06091"
"122.20000","0.10189","726.61737"
"122.40000","0.10205","728.18188"
"122.60000","0.10221","729.53046"
"122.80000","0.10232","730.99133"
"123.00000","0.10248","732.65027"
"123.20000","0.10270","734.15033"
"123.40000","0.10286","736.15210"
"123.60000","0.10302","737.90942"
"123.80000","0.10318","739.66901"
"124.00000","0.10334","741.28491"
"124.20000","0.10355","742.92639"
"124.40000","0.10371","744.66064"
"124.60000","0.10387","746.33624"
"124.80000","0.10404","748.27771"
"125.00000","0.10425","749.87598"
"125.20000","0.10441","751.55438"
"125.40000","0.10457","753.66235"
"125.60000","0.10473","755.04199"
"125.80000","0.10495","756.70056"
"126.00000","0.10511","758.52863"
"126.20000","0.10527","760.15369"
"126.40000","0.10543","761.58667"
"126.60000","0.10559","763.58673"
"126.80000","0.10575","764.88879"
"127.00000","0.10591","766.63293"
"127.20000","0.10607","768.19263"
"127.40000","0.10623","769.92957"
"127.60000","0.10639","771.50598"
"127.80000","0.10655","773.27277"
"128.00000","0.10671","774.75592"
"128.20000","0.10688","776.23401"
"128.40000","0.10704","777.55896"
"128.60000","0.10720","779.23633"
"128.80000","0.10736","780.80750"
"129.00000","0.10752","782.58972"
"129.20000","0.10768","784.10333"
"129.40000","0.10784","785.79877"
"129.60000","0.10800","787.43170"
"129.80000","0.10816","789.26770"
"130.00000","0.10837","791.19421"
"130.20000","0.10854","792.86896"
"130.40000","0.10870","794.65155"
"130.60000","0.10891","796.49786"
"130.80000","0.10907","798.54083"
"131.00000","0.10923","800.32013"
"131.20000","0.10945","801.89862"
"131.40000","0.10961","803.74744"
"131.60000","0.10977","805.29114"
"131.80000","0.10993","806.76691"
"132.00000","0.11009","808.72345"
"132.20000","0.11025","810.32977"
"132.40000","0.11041","811.89502"
"132.60000","0.11057","813.72351"
"132.80000","0.11079","815.27466"
"133.00000","0.11095","816.83380"
"133.20000","0.11111","818.84125"
"133.40000","0.11127","820.22034"
"133.60000","0.11143","821.91357"
"133.80000","0.11159","823.58423"
"134.00000","0.11175","825.21716"
"134.20000","0.11191","826.53430"
"134.40000","0.11207","828.46326"
"134.60000","0.11223","829.99402"
"134.80000","0.11239","831.31567"
"135.00000","0.11250","832.77472"
"135.20000","0.11266","834.24603"
"135.40000","0.11282","835.75739"
"135.60000","0.11304","837.56744"
"135.80000","0.11320","839.20477"
"136.00000","0.11336","840.98639"
"136.20000","0.11352","842.56207"
"136.40000","0.11368","844.48480"
"136.60000","0.11384","846.01630"
"136.80000","0.11405","847.71710"
"137.00000","0.11421","849.66180"
"137.20000","0.11437","851.30634"
"137.40000","0.11459","853.00641"
"137.60000","0.11475","854.63531"
"137.80000","0.11491","856.51392"
"138.00000","0.11507","858.14594"
"138.20000","0.11529","859.77570"
"138.40000","0.11545","861.36139"
"138.60000","0.11561","863.21106"
"138.80000","0.11577","864.60846"
"139.00000","0.11593","866.37915"
"139.20000","0.11609","868.30457"
"139.40000","0.11625","869.64154"
"139.60000","0.11641","871.25073"
"139.80000","0.11657","872.84161"
"140.00000","0.11673","874.52551"
"140.20000","0.11689","875.89484"
"140.40000","0.11705","877.44836"
"140.60000","0.11721","878.90741"
"140.80000","0.11732","880.27533"
"141.00000","0.11754","881.96576"
"141.20000","0.11770","883.51880"
"141.40000","0.11786","885.15894"
"141.60000","0.11802","886.74548"
"141.80000","0.11818","888.72968"
"142.00000","0.11834","890.38605"
"142.20000","0.11850","892.18878"
"142.40000","0.11871","893.62305"
"142.60000","0.11887","895.70734"
"142.80000","0.11904","897.51215"
"143.00000","0.11925","899.63446"
"143.20000","0.11941","901.19092"
"143.40000","0.11957","902.95099"
"143.60000","0.11973","904.46234"
"143.80000","0.11995","906.36383"
"144.00000","0.12011","907.90051"
"144.20000","0.12027","909.49567"
"144.40000","0.12043","911.26202"
"144.60000","0.12059","913.01624"
"144.80000","0.12075","914.77039"
"145.00000","0.12091","916.24408"
"145.20000","0.12107","917.98090"
"145.40000","0.12129","919.63580"
"145.60000","0.12145","921.24292"
"145.80000","0.12161","923.08429"
"146.00000","0.12177","924.53876"
"146.20000","0.12193","926.07880"
"146.40000","0.12209","927.84296"
"146.60000","0.12225","929.29443"
"146.80000","0.12241","930.73517"
"147.00000","0.12252","932.15387"
"147.20000","0.12268","933.60297"
"147.40000","0.12284","935.07025"
"147.60000","0.12300","936.64294"
"147.80000","0.12316","938.08539"
"148.00000","0.12338","939.80481"
"148.20000","0.12354","941.39734"
"148.40000","0.12370","942.90106"
"148.60000","0.12386","944.66730"
"148.80000","0.12402","946.59204"
"149.00000","0.12423","948.15552"
"149.20000","0.12439","949.87268"
"149.40000","0.12455","951.71149"
"149.60000","0.12471","953.46002"
"149.80000","0.12493","955.16559"
"150.00000","0.12509","956.62292"
"150.20000","0.12525","958.30511"
"150.40000","0.12541","960.14075"
"150.60000","0.12557","961.90674"
"150.80000","0.12573","963.44598"
"151.00000","0.12595","965.43811"
"151.20000","0.12611","966.95660"
"151.40000","0.12627","968.46887"
"151.60000","0.12643","970.25623"
"151.80000","0.12659","971.86310"
"152.00000","0.12675","973.50745"
"152.20000","0.12691","975.06354"
"152.40000","0.12707","976.66125"
"152.60000","0.12723","978.22211"
"152.80000","0.12734","979.60809"
"153.00000","0.12750","981.25867"
"153.20000","0.12766","982.81299"
"153.40000","0.12782","984.37195"
"153.60000","0.12804","985.98889"
"153.80000","0.12820","987.73352"
"154.00000","0.12836","989.40692"
"154.20000","0.12852","991.41150"
"154.40000","0.12868","992.94843"
"154.60000","0.12884","994.59662"
"154.80000","0.12905","996.41125"
"155.00000","0.12921","997.92023"
"155.20000","0.12943","999.79498"
"155.40000","0.12959","1001.56079"
"155.60000","0.12975","1003.47687"
"155.80000","0.12991","1004.78186"
"156.00000","0.13007","1006.50610"
"156.20000","0.13023","1008.25623"
"156.40000","0.13039","1009.85358"
"156.60000","0.13061","1011.53564"
"156.80000","0.13077","1013.07794"
"157.00000","0.13093","1014.78741"
"157.20000","0.13109","1016.32062"
"157.40000","0.13125","1018.02045"
"157.60000","0.13141","1019.51538"
"157.80000","0.13157","1021.47961"
"158.00000","0.13179","1022.96387"
"158.20000","0.13195","1024.49231"
"158.40000","0.13211","1026.25793"
"158.60000","0.13227","1027.65466"
"158.80000","0.13243","1029.25708"
"159.00000","0.13259","1030.90527"
"159.20000","0.13270","1032.31689"
"159.40000","0.13286","1033.70605"
"159.60000","0.13302","1035.14990"
"159.80000","0.13318","1037.02637"
"160.00000","0.13334","1038.48987"
"160.20000","0.13350","1040.28796"
"160.40000","0.13366","1041.89075"
"160.60000","0.13387","1043.55420"
"160.80000","0.13404","1045.48962"
"161.00000","0.13420","1047.23425"
"161.20000","0.13436","1048.85950"
"161.40000","0.13452","1050.60876"
"161.60000","0.13473","1052.27747"
"161.80000","0.13489","1054.42798"
"162.00000","0.13505","1055.86035"
"162.20000","0.13527","1057.99280"
"162.40000","0.13543","1059.60254"
"162.60000","0.13559","1061.41101"
"162.80000","0.13575","1062.93372"
"163.00000","0.13591","1064.44043"
"163.20000","0.13607","1066.12610"
"163.40000","0.13629","1067.92395"
"163.60000","0.13645","1069.44678"
"163.80000","0.13661","1071.11707"
"164.00000","0.13677","1072.49878"
"164.20000","0.13693","1074.21667"
"164.40000","0.13709","1075.82336"
"164.60000","0.13725","1077.48462"
"164.80000","0.13741","1078.82886"
"165.00000","0.13752","1080.17615"
"165.20000","0.13768","1081.73828"
"165.40000","0.13784","1083.30139"
"165.60000","0.13800","1084.68701"
"165.80000","0.13816","1086.39429"
"166.00000","0.13832","1088.10559"
"166.20000","0.13854","1089.61780"
"166.40000","0.13870","1091.52917"
"166.60000","0.13886","1092.96362"
"166.80000","0.13902","1094.80408"
"167.00000","0.13918","1096.62109"
"167.20000","0.13939","1098.22131"
"167.40000","0.13961","1100.39661"
"167.60000","0.13977","1102.12231"
"167.80000","0.13993","1103.50854"
"168.00000","0.14009","1105.11633"
"168.20000","0.14025","1106.66968"
"168.40000","0.14041","1108.36157"
"168.60000","0.14057","1109.96655"
"168.80000","0.14073","1111.65662"
"169.00000","0.14095","1113.49377"
"169.20000","0.14111","1115.09448"
"169.40000","0.14127","1116.72668"
"169.60000","0.14143","1118.30420"
"169.80000","0.14159","1119.97534"
"170.00000","0.14175","1121.91919"
"170.20000","0.14191","1123.47339"
"170.40000","0.14207","1125.01050"
"170.60000","0.14223","1126.56274"
"170.80000","0.14245","1128.32092"
"171.00000","0.14261","1129.99158"
"171.20000","0.14271","1131.44043"
"171.40000","0.14288","1132.75513"
"171.60000","0.14304","1134.08423"
"171.80000","0.14320","1135.67676"
"172.00000","0.14336","1137.12024"
"172.20000","0.14352","1138.99365"
"172.40000","0.14368","1140.69849"
"172.60000","0.14384","1142.55249"
"172.80000","0.14400","1144.07910"
"173.00000","0.14421","1145.86218"
"173.20000","0.14438","1147.68311"
"173.40000","0.14454","1149.38965"
"173.60000","0.14470","1151.13208"
"173.80000","0.14486","1152.69873"
"174.00000","0.14507","1154.42908"
"174.20000","0.14523","1156.41846"
"174.40000","0.14539","1157.96484"
"174.60000","0.14555","1159.86707"
"174.80000","0.14577","1161.73071"
"175.00000","0.14593","1163.43103"
"175.20000","0.14609","1164.95068"
"175.40000","0.14625","1166.63281"
"175.60000","0.14641","1168.28857"
"175.80000","0.14657","1169.97046"
"176.00000","0.14679","1171.82703"
"176.20000","0.14689","1173.16748"
"176.40000","0.14711","1174.68616"
"176.60000","0.14727","1176.53796"
"176.80000","0.14743","1178.05066"
"177.00000","0.14754","1179.68872"
"177.20000","0.14770","1180.97156"
"177.40000","0.14786","1182.37292"
"177.60000","0.14802","1184.02893"
"177.80000","0.14818","1185.43530"
"178.00000","0.14834","1187.39624"
"178.20000","0.14850","1188.98047"
"178.40000","0.14866","1190.40466"
"178.60000","0.14887","1192.16211"
"178.80000","0.14904","1193.91541"
"179.00000","0.14920","1195.54626"
"179.20000","0.14936","1197.18018"
"179.40000","0.14957","1199.01257"
"179.60000","0.14973","1201.11462"
"179.80000","0.14995","1202.81787"
"180.00000","0.15011","1204.34058"
"180.20000","0.15027","1205.97974"
"180.40000","0.15043","1207.53552"
"180.60000","0.15059","1209.27856"
"180.80000","0.15075","1210.93433"
"181.00000","0.15091","1212.56177"
"181.20000","0.15107","1214.30212"
"181.40000","0.15123","1216.02954"
"181.60000","0.15145","1217.56067"
"181.80000","0.15161","1219.48242"
"182.00000","0.15177","1221.11804"
"182.20000","0.15193","1222.82898"
"182.40000","0.15209","1224.39648"
"182.60000","0.15225","1226.11487"
"182.80000","0.15241","1227.75525"
"183.00000","0.15257","1229.47607"
"183.20000","0.15273","1231.16394"
"183.40000","0.15289","1232.86926"
"183.60000","0.15305","1234.42773"
"183.80000","0.15321","1235.69470"
"184.00000","0.15332","1237.03088"
"184.20000","0.15354","1238.72815"
"184.40000","0.15370","1240.41321"
"184.60000","0.15386","1242.00659"
"184.80000","0.15402","1243.82898"
"185.00000","0.15418","1245.42712"
"185.20000","0.15434","1247.51343"
"185.40000","0.15455","1248.91931"
"185.60000","0.15471","1250.50427"
"185.80000","0.15487","1252.20532"
"186.00000","0.15504","1253.98279"
"186.20000","0.15525","1255.75769"
"186.40000","0.15541","1257.12952"
"186.60000","0.15557","1258.82263"
"186.80000","0.15573","1260.90125"
"187.00000","0.15595","1262.28601"
"187.20000","0.15611","1264.11584"
"187.40000","0.15627","1265.32056"
"187.60000","0.15643","1267.08069"
"187.80000","0.15659","1268.88721"
"188.00000","0.15675","1270.60840"
"188.20000","0.15691","1272.05713"
"188.40000","0.15707","1273.57568"
"188.60000","0.15723","1275.24829"
"188.80000","0.15739","1276.73975"
"189.00000","0.15761","1278.42175"
"189.20000","0.15771","1280.13965"
"189.40000","0.15788","1281.38196"
"189.60000","0.15804","1282.78320"
"189.80000","0.15820","1284.16663"
"190.00000","0.15836","1285.96997"
"190.20000","0.15852","1287.68103"
"190.40000","0.15868","1289.34229"
"190.60000","0.15884","1290.78662"
"190.80000","0.15900","1292.55725"
"191.00000","0.15916","1294.09082"
"191.20000","0.15938","1295.96350"
"191.40000","0.15954","1297.80298"
"191.60000","0.15970","1299.46497"
"191.80000","0.15991","1301.16992"
"192.00000","0.16007","1303.17969"
"192.20000","0.16023","1304.99365"
"192.40000","0.16045","1306.52332"
"192.60000","0.16061","1307.86951"
"192.80000","0.16077","1309.89331"
"193.00000","0.16093","1311.47412"
"193.20000","0.16109","1312.81018"
"193.40000","0.16125","1314.47339"
"193.60000","0.16141","1316.24670"
"193.80000","0.16157","1317.88000"
"194.00000","0.16179","1319.54370"
"194.20000","0.16195","1320.92761"
"194.40000","0.16211","1322.91040"
"194.60000","0.16227","1324.43665"
"194.80000","0.16243","1325.94373"
"195.00000","0.16259","1327.36499"
"195.20000","0.16275","1329.13086"
"195.40000","0.16291","1330.66016"
"195.60000","0.16307","1332.20020"
"195.80000","0.16323","1333.41199"
"196.00000","0.16334","1334.87634"
"196.20000","0.16350","1336.27673"
"196.40000","0.16366","1337.95508"
"196.60000","0.16382","1339.33191"
"196.80000","0.16404","1341.13391"
"197.00000","0.16420","1342.84778"
"197.20000","0.16436","1344.39734"
"197.40000","0.16452","1346.03918"
"197.60000","0.16468","1347.75586"
"197.80000","0.16484","1349.53174"
"198.00000","0.16505","1351.23926"
"198.20000","0.16521","1352.84448"
"198.40000","0.16538","1354.53186"
"198.60000","0.16559","1356.09607"
"198.80000","0.16575","1358.05420"
"199.00000","0.16591","1359.68457"
"199.20000","0.16607","1361.47998"
"199.40000","0.16623","1363.06470"
"199.60000","0.16645","1364.39404"
"199.80000","0.16661","1366.22864"
"200.00000","0.16677","1367.95020"
"200.20000","0.16693","1369.43811"
"200.40000","0.16709","1371.14832"
"200.60000","0.16725","1372.81641"
"200.80000","0.16741","1374.38281"
"201.00000","0.16757","1376.02991"
"201.20000","0.16773","1377.28845"
"201.40000","0.16789","1379.10645"
"201.60000","0.16805","1380.32153"
"201.80000","0.16821","1381.72693"
"202.00000","0.16838","1383.17419"
"202.20000","0.16854","1384.56750"
"202.40000","0.16870","1386.04211"
"202.60000","0.16886","1387.67432"
"202.80000","0.16902","1389.30591"
"203.00000","0.16918","1390.92688"
"203.20000","0.16934","1392.57983"
"203.40000","0.16950","1394.32495"
"203.60000","0.16971","1395.78503"
"203.80000","0.16987","1397.53210"
"204.00000","0.17004","1399.35046"
"204.20000","0.17025","1401.35718"
"204.40000","0.17041","1403.03027"
"204.60000","0.17057","1404.49487"
"204.80000","0.17073","1406.11963"
"205.00000","0.17095","1407.56653"
"205.20000","0.17111","1409.26318"
"205.40000","0.17127","1410.97156"
"205.60000","0.17143","1412.65906"
"205.80000","0.17159","1413.99890"
"206.00000","0.17175","1415.67224"
"206.20000","0.17191","1417.51086"
"206.40000","0.17207","1418.89026"
"206.60000","0.17229","1420.49976"
"206.80000","0.17245","1422.10364"
"207.00000","0.17261","1423.95496"
"207.20000","0.17277","1425.15405"
"207.40000","0.17293","1426.95667"
"207.60000","0.17309","1428.45850"
"207.80000","0.17325","1430.34058"
"208.00000","0.17341","1431.54297"
"208.20000","0.17352","1433.10461"
"208.40000","0.17368","1434.00220"
"208.60000","0.17384","1435.62646"
"208.80000","0.17400","1437.31055"
"209.00000","0.17416","1438.99829"
"209.20000","0.17432","1440.64392"
"209.40000","0.17454","1442.41895"
"209.60000","0.17470","1443.67358"
"209.80000","0.17486","1445.41577"
"210.00000","0.17502","1447.05969"
"210.20000","0.17523","1448.81775"
"210.40000","0.17539","1450.38013"
"210.60000","0.17555","1451.89355"
"210.80000","0.17571","1453.64404"
"211.00000","0.17587","1455.17297"
"211.20000","0.17609","1456.98279"
"211.40000","0.17625","1458.22339"
"211.60000","0.17641","1460.06787"
"211.80000","0.17657","1461.42383"
"212.00000","0.17679","1463.16199"
"212.20000","0.17695","1464.56409"
"212.40000","0.17711","1466.05347"
"212.60000","0.17727","1467.45117"
"212.80000","0.17743","1468.99683"
"213.00000","0.17759","1470.64746"
"213.20000","0.17775","1472.12439"
"213.40000","0.17791","1473.89441"
"213.60000","0.17807","1475.10803"
"213.80000","0.17823","1476.54578"
"214.00000","0.17834","1477.59644"
"214.20000","0.17850","1479.30188"
"214.40000","0.17866","1480.73657"
"214.60000","0.17882","1482.02979"
"214.80000","0.17904","1483.58862"
"215.00000","0.17920","1485.19165"
"215.20000","0.17936","1486.65906"
"215.40000","0.17952","1488.35059"
"215.60000","0.17968","1490.12598"
"215.80000","0.17984","1491.19495"
"216.00000","0.18005","1492.86401"
"216.20000","0.18021","1494.62427"
"216.40000","0.18038","1496.34863"
"216.60000","0.18059","1497.99609"
"216.80000","0.18075","1499.41528"
"217.00000","0.18091","1500.80420"
"217.20000","0.18107","1502.35522"
"217.40000","0.18123","1503.54248"
"217.60000","0.18139","1505.13721"
"217.80000","0.18161","1506.59607"
"218.00000","0.18177","1508.09729"
"218.20000","0.18193","1509.61255"
"218.40000","0.18209","1511.06970"
"218.60000","0.18225","1512.28613"
"218.80000","0.18241","1513.86792"
"219.00000","0.18257","1515.47119"
"219.20000","0.18279","1516.62329"
"219.40000","0.18295","1518.12585"
"219.60000","0.18311","1519.56885"
"219.80000","0.18327","1521.12109"
"220.00000","0.18343","1522.05505"
"220.20000","0.18359","1523.26257"
"220.40000","0.18370","1524.61438"
"220.60000","0.18386","1525.94238"
"220.80000","0.18402","1527.25903"
"221.00000","0.18418","1528.46423"
"221.20000","0.18434","1530.00586"
"221.40000","0.18450","1531.17847"
"221.60000","0.18466","1532.71509"
"221.80000","0.18487","1534.07629"
"222.00000","0.18504","1535.34595"
"222.20000","0.18520","1537.05481"
"222.40000","0.18536","1538.26233"
"222.60000","0.18552","1539.70789"
"222.80000","0.18573","1540.98755"
"223.00000","0.18589","1542.63513"
"223.20000","0.18605","1543.69666"
"223.40000","0.18627","1545.27979"
"223.60000","0.18643","1546.46509"
"223.80000","0.18659","1547.93750"
"224.00000","0.18675","1549.11658"
"224.20000","0.18691","1550.58704"
"224.40000","0.18707","1551.61304"
"224.60000","0.18723","1552.99585"
"224.80000","0.18745","1554.27197"
"225.00000","0.18761","1555.84045"
"225.20000","0.18777","1556.71204"
"225.40000","0.18793","1558.23169"
"225.60000","0.18809","1558.93921"
"225.80000","0.18825","1560.61694"
"226.00000","0.18841","1561.37854"
"226.20000","0.18852","1562.39697"
"226.40000","0.18868","1563.66785"
"226.60000","0.18884","1564.48413"
"226.80000","0.18900","1565.70032"
"227.00000","0.18916","1566.97461"
"227.20000","0.18932","1567.86609"
"227.40000","0.18954","1569.20178"
"227.60000","0.18970","1570.12402"
"227.80000","0.18986","1571.19128"
"228.00000","0.19002","1572.46106"
"228.20000","0.19018","1573.46008"
"228.40000","0.19039","1574.67139"
"228.60000","0.19055","1575.94141"
"228.80000","0.19077","1576.97754"
"229.00000","0.19093","1578.13525"
"229.20000","0.19109","1579.03821"
"229.40000","0.19125","1579.91284"
"229.60000","0.19141","1580.86145"
"229.80000","0.19157","1581.82654"
"230.00000","0.19173","1582.86279"
"230.20000","0.19195","1583.72449"
"230.40000","0.19211","1584.56812"
"230.60000","0.19227","1585.60938"
"230.80000","0.19243","1586.48730"
"231.00000","0.19259","1587.35388"
"231.20000","0.19275","1588.20728"
"231.40000","0.19291","1589.08093"
"231.60000","0.19307","1589.89722"
"231.80000","0.19329","1590.78491"
"232.00000","0.19345","1591.63757"
"232.20000","0.19361","1592.15430"
"232.40000","0.19377","1592.93457"
"232.60000","0.19387","1593.96362"
"232.80000","0.19404","1594.45654"
"233.00000","0.19420","1595.07922"
"233.20000","0.19436","1595.77551"
"233.40000","0.19452","1596.60413"
"233.60000","0.19468","1597.17896"
"233.80000","0.19484","1597.95044"
"234.00000","0.19500","1598.89661"
"234.20000","0.19521","1599.43738"
"234.40000","0.19538","1600.59021"
"234.60000","0.19554","1600.73352"
"234.80000","0.19570","1601.53931"
"235.00000","0.19586","1602.02124"
"235.20000","0.19602","1602.81799"
"235.40000","0.19623","1603.57886"
"235.60000","0.19639","1604.19446"
"235.80000","0.19655","1604.85925"
"236.00000","0.19671","1605.56848"
"236.20000","0.19693","1606.37500"
"236.40000","0.19709","1606.83008"
"236.60000","0.19725","1607.40356"
"236.80000","0.19741","1608.12610"
"237.00000","0.19757","1608.66321"
"237.20000","0.19779","1609.03198"
"237.40000","0.19795","1609.76453"
"237.60000","0.19811","1610.04602"
"237.80000","0.19827","1610.70068"
"238.00000","0.19843","1611.20862"
"238.20000","0.19854","1611.81311"
"238.40000","0.19870","1611.88367"
"238.60000","0.19886","1612.65356"
"238.80000","0.19902","1613.05530"
"239.00000","0.19918","1613.55591"
"239.20000","0.19934","1613.98364"
"239.40000","0.19950","1614.36890"
"239.60000","0.19966","1614.84912"
"239.80000","0.19987","1615.33813"
"240.00000","0.20004","1615.71448"
"240.20000","0.20020","1616.17212"
"240.40000","0.20036","1616.60229"
"240.60000","0.20052","1617.14001"
"240.80000","0.20073","1617.41931"
"241.00000","0.20095","1617.81433"
"241.20000","0.20111","1618.42529"
"241.40000","0.20127","1618.71741"
"241.60000","0.20143","1619.20605"
"241.80000","0.20159","1619.36877"
"242.00000","0.20175","1619.74353"
"242.20000","0.20191","1620.00659"
"242.40000","0.20207","1620.47717"
"242.60000","0.20229","1620.87231"
"242.80000","0.20245","1621.14954"
"243.00000","0.20261","1621.52393"
"243.20000","0.20277","1621.69800"
"243.40000","0.20293","1622.15723"
"243.60000","0.20309","1622.37671"
"243.80000","0.20325","1622.74158"
"244.00000","0.20341","1623.08215"
"244.20000","0.20357","1623.35901"
"244.40000","0.20373","1623.55481"
"244.60000","0.20389","1623.90735"
"244.80000","0.20405","1624.12561"
"245.00000","0.20421","1624.28308"
"245.20000","0.20432","1624.68469"
"245.40000","0.20454","1624.81677"
"245.60000","0.20470","1625.45703"
"245.80000","0.20486","1625.35583"
"246.00000","0.20502","1625.54199"
"246.20000","0.20518","1625.92041"
"246.40000","0.20534","1626.14038"
"246.60000","0.20555","1626.48267"
"246.80000","0.20571","1626.80090"
"247.00000","0.20587","1627.01526"
"247.20000","0.20604","1627.21008"
"247.40000","0.20620","1627.42871"
"247.60000","0.20641","1627.70667"
"247.80000","0.20657","1627.89148"
"248.00000","0.20673","1628.09558"
"248.20000","0.20689","1628.36731"
"248.40000","0.20711","1628.61523"
"248.60000","0.20727","1628.66711"
"248.80000","0.20743","1628.86548"
"249.00000","0.20759","1629.28845"
"249.20000","0.20775","1629.36560"
"249.40000","0.20791","1629.58960"
"249.60000","0.20807","1629.59875"
"249.80000","0.20823","1629.95227"
"250.00000","0.20839","1630.31421"
"250.20000","0.20855","1630.18152"
"250.40000","0.20871","1630.50330"
"250.60000","0.20888","1630.60461"
"250.80000","0.20904","1631.42554"
"251.00000","0.20920","1630.78857"
"251.20000","0.20936","1631.20300"
"251.40000","0.20952","1631.22278"
"251.60000","0.20968","1631.53638"
"251.80000","0.20984","1631.50854"
"252.00000","0.21000","1631.90198"
"252.20000","0.21016","1631.72046"
"252.40000","0.21037","1632.33850"
"252.60000","0.21054","1632.47644"
"252.80000","0.21070","1632.36609"
"253.00000","0.21091","1632.74146"
"253.20000","0.21107","1632.89343"
"253.27200","0.21118","1632.88635"